"""This module contains the image generation API."""

import os
import sys
import urllib.request
from pathlib import Path

sys.path.append(os.path.join(os.path.dirname(__file__), "libs"))

import openai

openai.api_key = os.getenv("api_key")
__size = int(os.getenv("image_size") or 512)


def get_query() -> str:
    """Join the arguments into a query string."""
    return " ".join(sys.argv[1:])


def prepare_file_name(prompt: str) -> str:
    """Prepares the file name."""
    return (
        prompt.replace(" ", "_")
        .replace(",", "")
        .replace(".", "")
        .replace('"', "")
        .replace(":", "")
        .replace("'", "")
        .replace("/", "")
        .replace("\\", "")
    )


def make_request(prompt: str, size: int) -> str:
    """Makes the request to the OpenAI API."""
    file_path = f"{str(Path.home())}/ChatFred_{prepare_file_name(prompt)}.png"

    try:
        response = openai.Image.create(prompt=prompt, n=1, size=f"{size}x{size}")
        urllib.request.urlretrieve(response["data"][0]["url"], file_path)  # nosec
        return file_path

    except openai.error.AuthenticationError:
        return "ðŸš¨ There seems to be something wrong! Please check your API key."

    except openai.error.InvalidRequestError as error:
        if str(error).startswith(
            "Your request was rejected as a result of our safety system"
        ):
            return "ðŸš¨ You shouldn't generate such stuff! Your prompt was declined by OpenAI's safety system."
        return "ðŸš¨ Hmmm... Something is wrong with your request. Try again later."

    except openai.error.ServiceUnavailableError:
        return "ðŸš¨ Oh no! The server is overloaded or not ready yet."

    except openai.error.APIError:
        return "ðŸš¨ D'oh! The server had an error while processing your request."

    except openai.error.APIConnectionError:
        return "ðŸš¨ There is something fishy with your internet connection. Check your network settings."

    except openai.error.RateLimitError:
        return "ðŸš¨ You have reached the rate limit. Check your settings in your OpenAI dashboard."

    except openai.error.Timeout:
        return "ðŸš¨ The request timed out. Try again later."


__response = make_request(get_query(), __size)
sys.stdout.write(__response)
